Traceback (most recent call last):
  File "/Users/veershah/anaconda3/bin/uvicorn", line 8, in <module>
    sys.exit(main())
             ^^^^^^
  File "/Users/veershah/anaconda3/lib/python3.11/site-packages/click/core.py", line 1161, in __call__
    return self.main(*args, **kwargs)
           ^^^^^^^^^^^^^^^^^^^^^^^^^^
  File "/Users/veershah/anaconda3/lib/python3.11/site-packages/click/core.py", line 1082, in main
    rv = self.invoke(ctx)
         ^^^^^^^^^^^^^^^^
  File "/Users/veershah/anaconda3/lib/python3.11/site-packages/click/core.py", line 1443, in invoke
    return ctx.invoke(self.callback, **ctx.params)
           ^^^^^^^^^^^^^^^^^^^^^^^^^^^^^^^^^^^^^^^
  File "/Users/veershah/anaconda3/lib/python3.11/site-packages/click/core.py", line 788, in invoke
    return __callback(*args, **kwargs)
           ^^^^^^^^^^^^^^^^^^^^^^^^^^^
  File "/Users/veershah/anaconda3/lib/python3.11/site-packages/uvicorn/main.py", line 416, in main
    run(
  File "/Users/veershah/anaconda3/lib/python3.11/site-packages/uvicorn/main.py", line 587, in run
    server.run()
  File "/Users/veershah/anaconda3/lib/python3.11/site-packages/uvicorn/server.py", line 61, in run
    return asyncio.run(self.serve(sockets=sockets))
           ^^^^^^^^^^^^^^^^^^^^^^^^^^^^^^^^^^^^^^^^
  File "/Users/veershah/anaconda3/lib/python3.11/asyncio/runners.py", line 190, in run
    return runner.run(main)
           ^^^^^^^^^^^^^^^^
  File "/Users/veershah/anaconda3/lib/python3.11/asyncio/runners.py", line 118, in run
    return self._loop.run_until_complete(task)
           ^^^^^^^^^^^^^^^^^^^^^^^^^^^^^^^^^^^
  File "/Users/veershah/anaconda3/lib/python3.11/asyncio/base_events.py", line 653, in run_until_complete
    return future.result()
           ^^^^^^^^^^^^^^^
  File "/Users/veershah/anaconda3/lib/python3.11/site-packages/uvicorn/server.py", line 68, in serve
    config.load()
  File "/Users/veershah/anaconda3/lib/python3.11/site-packages/uvicorn/config.py", line 467, in load
    self.loaded_app = import_from_string(self.app)
                      ^^^^^^^^^^^^^^^^^^^^^^^^^^^^
  File "/Users/veershah/anaconda3/lib/python3.11/site-packages/uvicorn/importer.py", line 21, in import_from_string
    module = importlib.import_module(module_str)
             ^^^^^^^^^^^^^^^^^^^^^^^^^^^^^^^^^^^
  File "/Users/veershah/anaconda3/lib/python3.11/importlib/__init__.py", line 126, in import_module
    return _bootstrap._gcd_import(name[level:], package, level)
           ^^^^^^^^^^^^^^^^^^^^^^^^^^^^^^^^^^^^^^^^^^^^^^^^^^^^
  File "<frozen importlib._bootstrap>", line 1204, in _gcd_import
  File "<frozen importlib._bootstrap>", line 1176, in _find_and_load
  File "<frozen importlib._bootstrap>", line 1147, in _find_and_load_unlocked
  File "<frozen importlib._bootstrap>", line 690, in _load_unlocked
  File "<frozen importlib._bootstrap_external>", line 940, in exec_module
  File "<frozen importlib._bootstrap>", line 241, in _call_with_frames_removed
  File "/Users/veershah/Desktop/TradeTide /yfinance_api.py", line 4, in <module>
    import yfinance as yf
  File "/Users/veershah/anaconda3/lib/python3.11/site-packages/yfinance/__init__.py", line 23, in <module>
    from .ticker import Ticker
  File "/Users/veershah/anaconda3/lib/python3.11/site-packages/yfinance/ticker.py", line 27, in <module>
    import pandas as _pd
  File "/Users/veershah/anaconda3/lib/python3.11/site-packages/pandas/__init__.py", line 22, in <module>
    from pandas.compat import is_numpy_dev as _is_numpy_dev  # pyright: ignore # noqa:F401
    ^^^^^^^^^^^^^^^^^^^^^^^^^^^^^^^^^^^^^^^^^^^^^^^^^^^^^^^
  File "/Users/veershah/anaconda3/lib/python3.11/site-packages/pandas/compat/__init__.py", line 25, in <module>
    from pandas.compat.numpy import (
  File "/Users/veershah/anaconda3/lib/python3.11/site-packages/pandas/compat/numpy/__init__.py", line 4, in <module>
    from pandas.util.version import Version
  File "/Users/veershah/anaconda3/lib/python3.11/site-packages/pandas/util/__init__.py", line 2, in <module>
    from pandas.util._decorators import (  # noqa:F401
  File "/Users/veershah/anaconda3/lib/python3.11/site-packages/pandas/util/_decorators.py", line 14, in <module>
    from pandas._libs.properties import cache_readonly
  File "/Users/veershah/anaconda3/lib/python3.11/site-packages/pandas/_libs/__init__.py", line 13, in <module>
    from pandas._libs.interval import Interval
  File "pandas/_libs/interval.pyx", line 1, in init pandas._libs.interval
ValueError: numpy.dtype size changed, may indicate binary incompatibility. Expected 96 from C header, got 88 from PyObject
